(venv) grader@ip-172-26-12-6:/var/www/catalog/catalog$ sudo tail -10 /var/log/apache2/error.log
[Wed May 31 03:41:36.795854 2017] [wsgi:error] [pid 23654:tid 140268792153856] [remote 67.164.34.80:65246]     execution_options=execution_options)
[Wed May 31 03:41:36.795855 2017] [wsgi:error] [pid 23654:tid 140268792153856] [remote 67.164.34.80:65246]   File "/usr/local/lib/python2.7/dist-pac                                                              kages/sqlalchemy/orm/session.py", line 1003, in _connection_for_bind
[Wed May 31 03:41:36.795857 2017] [wsgi:error] [pid 23654:tid 140268792153856] [remote 67.164.34.80:65246]     engine, execution_options)
[Wed May 31 03:41:36.795859 2017] [wsgi:error] [pid 23654:tid 140268792153856] [remote 67.164.34.80:65246]   File "/usr/local/lib/python2.7/dist-pac                                                              kages/sqlalchemy/orm/session.py", line 382, in _connection_for_bind
[Wed May 31 03:41:36.795860 2017] [wsgi:error] [pid 23654:tid 140268792153856] [remote 67.164.34.80:65246]     self._assert_active()
[Wed May 31 03:41:36.795862 2017] [wsgi:error] [pid 23654:tid 140268792153856] [remote 67.164.34.80:65246]   File "/usr/local/lib/python2.7/dist-pac                                                              kages/sqlalchemy/orm/session.py", line 276, in _assert_active
[Wed May 31 03:41:36.795864 2017] [wsgi:error] [pid 23654:tid 140268792153856] [remote 67.164.34.80:65246]     % self._rollback_exception
[Wed May 31 03:41:36.795866 2017] [wsgi:error] [pid 23654:tid 140268792153856] [remote 67.164.34.80:65246] InvalidRequestError: This Session's trans                                                              action has been rolled back due to a previous exception during flush. To begin a new transaction with this Session, first issue Session.rollback().                                                               Original exception was: (psycopg2.IntegrityError) duplicate key value violates unique constraint "item_information_pkey"
[Wed May 31 03:41:36.795868 2017] [wsgi:error] [pid 23654:tid 140268792153856] [remote 67.164.34.80:65246] DETAIL:  Key (id)=(3) already exists.
[Wed May 31 03:41:36.795870 2017] [wsgi:error] [pid 23654:tid 140268792153856] [remote 67.164.34.80:65246]  [SQL: 'INSERT INTO item_information (nam                                                              e, description, image, price, make, category_id, user_id) VALUES (%(name)s, %(description)s, %(image)s, %(price)s, %(make)s, %(category_id)s, %(user                                                              _id)s) RETURNING item_information.id'] [parameters: {'user_id': 1, 'description': u'Light Brown Cocnuts', 'price': u'$2.99', 'name': u'Light Brown C                                                              oconuts', 'category_id': 4, 'image': None, 'make': u'Japanese'}]

(venv) grader@ip-172-26-12-6:/var/www/catalog/catalog$ sudo service apache2 restart
(venv) grader@ip-172-26-12-6:/var/www/catalog/catalog$ sudo tail -10 /var/log/apache2/error.log
[Wed May 31 11:01:54.778453 2017] [wsgi:error] [pid 25827:tid 140635444365056] [remote 67.164.34.80:3652]   File "/usr/local/lib/python2.7/dist-packages/sqlalchemy/orm/session.py", line 998, in connection
[Wed May 31 11:01:54.778455 2017] [wsgi:error] [pid 25827:tid 140635444365056] [remote 67.164.34.80:3652]     execution_options=execution_options)
[Wed May 31 11:01:54.778457 2017] [wsgi:error] [pid 25827:tid 140635444365056] [remote 67.164.34.80:3652]   File "/usr/local/lib/python2.7/dist-packages/sqlalchemy/orm/session.py", line 1003, in _connection_for_bind
[Wed May 31 11:01:54.778458 2017] [wsgi:error] [pid 25827:tid 140635444365056] [remote 67.164.34.80:3652]     engine, execution_options)
[Wed May 31 11:01:54.778460 2017] [wsgi:error] [pid 25827:tid 140635444365056] [remote 67.164.34.80:3652]   File "/usr/local/lib/python2.7/dist-packages/sqlalchemy/orm/session.py", line 382, in _connection_for_bind
[Wed May 31 11:01:54.778465 2017] [wsgi:error] [pid 25827:tid 140635444365056] [remote 67.164.34.80:3652]     self._assert_active()
[Wed May 31 11:01:54.778467 2017] [wsgi:error] [pid 25827:tid 140635444365056] [remote 67.164.34.80:3652]   File "/usr/local/lib/python2.7/dist-packages/sqlalchemy/orm/session.py", line 276, in _assert_active
[Wed May 31 11:01:54.778469 2017] [wsgi:error] [pid 25827:tid 140635444365056] [remote 67.164.34.80:3652]     % self._rollback_exception
[Wed May 31 11:01:54.778471 2017] [wsgi:error] [pid 25827:tid 140635444365056] [remote 67.164.34.80:3652] InvalidRequestError: This Session's transaction has been rolled back due to a previous exception during flush. To begin a new transaction with this Session, first issue Session.rollback(). Original exception was: (psycopg2.DataError) value too long for type character varying(8)
[Wed May 31 11:01:54.778474 2017] [wsgi:error] [pid 25827:tid 140635444365056] [remote 67.164.34.80:3652]  [SQL: 'INSERT INTO item_information (name, description, image, price, make, category_id, user_id) VALUES (%(name)s, %(description)s, %(image)s, %(price)s, %(make)s, %(category_id)s, %(user_id)s) RETURNING item_information.id'] [parameters: {'user_id': 2, 'description': u'Luxury Sedan', 'price': u'$45000.00', 'name': u'325i', 'category_id': 2, 'image': None, 'make': u'Germany'}]
